<?xml version="1.0"?>
<robot xmlns:xacro="http://www.ros.org/wiki/xacro">
    <xacro:macro name="swerve_wheel" params="prefix x_reflect y_reflect">
        
        <link name="${prefix}_steer_link">
            <visual>
                <origin xyz="0 0 -0.02" rpy="0 0 0"/>
                <geometry>
                    <cylinder radius="0.02" length="0.04"/>
                </geometry>
                <material name="blue"/>
            </visual>
            <xacro:inertial_cylinder mass="0.5" length="0.04" radius="0.02">
                <origin xyz="0 0 -0.02" rpy="0 0 0"/>
            </xacro:inertial_cylinder>
        </link>

        <joint name="${prefix}_steer_joint" type="revolute">
            <parent link="base_link"/>
            <child link="${prefix}_steer_link"/>
            <origin xyz="${x_reflect * wheel_x_offset} ${y_reflect * wheel_y_offset} ${steer_z_offset}" rpy="0 0 0"/>
            <axis xyz="0 0 1"/> 
            <limit lower="-${steer_limit}" upper="${steer_limit}" effort="10.0" velocity="2.0"/>
        </joint>

        <link name="${prefix}_wheel_link">
            <visual>
                <origin xyz="0 0 0" rpy="${pi/2} 0 0"/>
                <geometry>
                    <cylinder radius="${wheel_radius}" length="${wheel_width}"/>
                </geometry>
                <material name="black"/>
            </visual>
            <collision>
                <origin xyz="0 0 0" rpy="${pi/2} 0 0"/>
                <geometry>
                    <cylinder radius="${wheel_radius}" length="${wheel_width}"/>
                </geometry>
            </collision>
            <xacro:inertial_cylinder mass="1.5" length="${wheel_width}" radius="${wheel_radius}">
                <origin xyz="0 0 0" rpy="${pi/2} 0 0"/>
            </xacro:inertial_cylinder>
        </link>

        <joint name="${prefix}_drive_joint" type="continuous">
            <parent link="${prefix}_steer_link"/>
            <child link="${prefix}_wheel_link"/>
            <origin xyz="0 0 -0.04" rpy="0 0 0"/>
            <axis xyz="0 1 0"/> 
        </joint>
    </xacro:macro>
</robot>